[2022-05-28 16:50:09,254] {taskinstance.py:1160} INFO - Dependencies all met for <TaskInstance: Gamer_Daily_Request.get_lottery manual__2022-05-28T08:49:58.886626+00:00 [queued]>
[2022-05-28 16:50:09,259] {taskinstance.py:1160} INFO - Dependencies all met for <TaskInstance: Gamer_Daily_Request.get_lottery manual__2022-05-28T08:49:58.886626+00:00 [queued]>
[2022-05-28 16:50:09,259] {taskinstance.py:1357} INFO - 
--------------------------------------------------------------------------------
[2022-05-28 16:50:09,259] {taskinstance.py:1358} INFO - Starting attempt 1 of 1
[2022-05-28 16:50:09,260] {taskinstance.py:1359} INFO - 
--------------------------------------------------------------------------------
[2022-05-28 16:50:09,268] {taskinstance.py:1378} INFO - Executing <Task(_PythonDecoratedOperator): get_lottery> on 2022-05-28 08:49:58.886626+00:00
[2022-05-28 16:50:09,270] {standard_task_runner.py:52} INFO - Started process 38025 to run task
[2022-05-28 16:50:09,274] {standard_task_runner.py:79} INFO - Running: ['airflow', 'tasks', 'run', 'Gamer_Daily_Request', 'get_lottery', 'manual__2022-05-28T08:49:58.886626+00:00', '--job-id', '103', '--raw', '--subdir', 'DAGS_FOLDER/gamer_dag.py', '--cfg-path', '/var/folders/7p/8y53sxp17879s6k6nzygbwgw0000gn/T/tmpj1hsf154', '--error-file', '/var/folders/7p/8y53sxp17879s6k6nzygbwgw0000gn/T/tmpnv258q5v']
[2022-05-28 16:50:09,275] {standard_task_runner.py:80} INFO - Job 103: Subtask get_lottery
[2022-05-28 16:50:09,313] {task_command.py:370} INFO - Running <TaskInstance: Gamer_Daily_Request.get_lottery manual__2022-05-28T08:49:58.886626+00:00 [running]> on host userdeMacBook-Pro.local
[2022-05-28 16:50:09,352] {taskinstance.py:1570} INFO - Exporting the following env vars:
AIRFLOW_CTX_DAG_EMAIL=b01201008@gmail.com
AIRFLOW_CTX_DAG_OWNER=randy
AIRFLOW_CTX_DAG_ID=Gamer_Daily_Request
AIRFLOW_CTX_TASK_ID=get_lottery
AIRFLOW_CTX_EXECUTION_DATE=2022-05-28T08:49:58.886626+00:00
AIRFLOW_CTX_TRY_NUMBER=1
AIRFLOW_CTX_DAG_RUN_ID=manual__2022-05-28T08:49:58.886626+00:00
[2022-05-28 16:50:09,353] {logging_mixin.py:115} INFO - get_lottery
[2022-05-28 16:50:30,171] {logging_mixin.py:115} INFO - Message: no such element: Unable to locate element: {"method":"css selector","selector":"div[class*='rewardDialogueWrapper']:not([style*='display']) > div.rewardResumebutton"}
  (Session info: chrome=102.0.5005.61)
Stacktrace:
0   chromedriver                        0x000000010a6f7d19 chromedriver + 5197081
1   chromedriver                        0x000000010a685b23 chromedriver + 4729635
2   chromedriver                        0x000000010a2632b8 chromedriver + 393912
3   chromedriver                        0x000000010a2982fd chromedriver + 611069
4   chromedriver                        0x000000010a298581 chromedriver + 611713
5   chromedriver                        0x000000010a2ca5a4 chromedriver + 816548
6   chromedriver                        0x000000010a2b582d chromedriver + 731181
7   chromedriver                        0x000000010a2c82a1 chromedriver + 807585
8   chromedriver                        0x000000010a2b56f3 chromedriver + 730867
9   chromedriver                        0x000000010a28ba49 chromedriver + 559689
10  chromedriver                        0x000000010a28ca75 chromedriver + 563829
11  chromedriver                        0x000000010a6c9bdd chromedriver + 5008349
12  chromedriver                        0x000000010a6ceb64 chromedriver + 5028708
13  chromedriver                        0x000000010a6d3bcf chromedriver + 5049295
14  chromedriver                        0x000000010a6cf7ca chromedriver + 5031882
15  chromedriver                        0x000000010a6a959f chromedriver + 4875679
16  chromedriver                        0x000000010a6e9388 chromedriver + 5137288
17  chromedriver                        0x000000010a6e950f chromedriver + 5137679
18  chromedriver                        0x000000010a6ff085 chromedriver + 5226629
19  libsystem_pthread.dylib             0x00007ff819e344e1 _pthread_start + 125
20  libsystem_pthread.dylib             0x00007ff819e2ff6b thread_start + 15
[2022-05-28 16:50:30,171] {logging_mixin.py:115} INFO - fail to click div[class*='rewardDialogueWrapper']:not([style*='display']) > div.rewardResumebutton
[2022-05-28 16:51:00,456] {local_task_job.py:193} ERROR - The recorded hostname userdeMacBook-Pro.local does not match this instance's hostname 1.0.0.0.0.0.0.0.0.0.0.0.0.0.0.0.0.0.0.0.0.0.0.0.0.0.0.0.0.0.0.0.ip6.arpa
[2022-05-28 16:51:00,471] {process_utils.py:125} INFO - Sending Signals.SIGTERM to group 38025. PIDs of all processes in the group: [38026, 38027, 38035, 38036, 38037, 38040, 38043, 38046, 38047, 38048, 38025]
[2022-05-28 16:51:00,471] {process_utils.py:80} INFO - Sending the signal Signals.SIGTERM to group 38025
[2022-05-28 16:51:00,471] {taskinstance.py:1542} ERROR - Received SIGTERM. Terminating subprocesses.
[2022-05-28 16:51:00,494] {taskinstance.py:1890} ERROR - Task failed with exception
Traceback (most recent call last):
  File "/Users/user/.pyenv/versions/3.8.13/lib/python3.8/site-packages/airflow/decorators/base.py", line 179, in execute
    return_value = super().execute(context)
  File "/Users/user/.pyenv/versions/3.8.13/lib/python3.8/site-packages/airflow/operators/python.py", line 171, in execute
    return_value = self.execute_callable()
  File "/Users/user/.pyenv/versions/3.8.13/lib/python3.8/site-packages/airflow/operators/python.py", line 189, in execute_callable
    return self.python_callable(*self.op_args, **self.op_kwargs)
  File "/Users/user/flow-for-randy/dags/gamer_dag.py", line 32, in get_lottery
    gamer_service.get_lotteries()
  File "/Users/user/flow-for-randy/dags/services/gamer.py", line 74, in get_lotteries
    self.get_lottery(lottery_page)
  File "/Users/user/flow-for-randy/dags/services/gamer.py", line 66, in get_lottery
    self.watch_ad()
  File "/Users/user/flow-for-randy/dags/services/gamer.py", line 59, in watch_ad
    self.browser.click(GamerElement.close_button)
  File "/Users/user/flow-for-randy/dags/services/drivers/selenium_driver.py", line 32, in click
    self.find_element(el).click()
  File "/Users/user/.pyenv/versions/3.8.13/lib/python3.8/site-packages/selenium/webdriver/remote/webelement.py", line 89, in click
    self._execute(Command.CLICK_ELEMENT)
  File "/Users/user/.pyenv/versions/3.8.13/lib/python3.8/site-packages/selenium/webdriver/remote/webelement.py", line 773, in _execute
    return self._parent.execute(command, params)
  File "/Users/user/.pyenv/versions/3.8.13/lib/python3.8/site-packages/selenium/webdriver/remote/webdriver.py", line 428, in execute
    response = self.command_executor.execute(driver_command, params)
  File "/Users/user/.pyenv/versions/3.8.13/lib/python3.8/site-packages/selenium/webdriver/remote/remote_connection.py", line 347, in execute
    return self._request(command_info[0], url, body=data)
  File "/Users/user/.pyenv/versions/3.8.13/lib/python3.8/site-packages/selenium/webdriver/remote/remote_connection.py", line 369, in _request
    response = self._conn.request(method, url, body=body, headers=headers)
  File "/Users/user/.pyenv/versions/3.8.13/lib/python3.8/site-packages/urllib3/request.py", line 78, in request
    return self.request_encode_body(
  File "/Users/user/.pyenv/versions/3.8.13/lib/python3.8/site-packages/urllib3/request.py", line 170, in request_encode_body
    return self.urlopen(method, url, **extra_kw)
  File "/Users/user/.pyenv/versions/3.8.13/lib/python3.8/site-packages/urllib3/poolmanager.py", line 376, in urlopen
    response = conn.urlopen(method, u.request_uri, **kw)
  File "/Users/user/.pyenv/versions/3.8.13/lib/python3.8/site-packages/urllib3/connectionpool.py", line 703, in urlopen
    httplib_response = self._make_request(
  File "/Users/user/.pyenv/versions/3.8.13/lib/python3.8/site-packages/urllib3/connectionpool.py", line 449, in _make_request
    six.raise_from(e, None)
  File "<string>", line 3, in raise_from
  File "/Users/user/.pyenv/versions/3.8.13/lib/python3.8/site-packages/urllib3/connectionpool.py", line 444, in _make_request
    httplib_response = conn.getresponse()
  File "/Users/user/.pyenv/versions/3.8.13/lib/python3.8/http/client.py", line 1348, in getresponse
    response.begin()
  File "/Users/user/.pyenv/versions/3.8.13/lib/python3.8/http/client.py", line 316, in begin
    version, status, reason = self._read_status()
  File "/Users/user/.pyenv/versions/3.8.13/lib/python3.8/http/client.py", line 277, in _read_status
    line = str(self.fp.readline(_MAXLINE + 1), "iso-8859-1")
  File "/Users/user/.pyenv/versions/3.8.13/lib/python3.8/socket.py", line 669, in readinto
    return self._sock.recv_into(b)
  File "/Users/user/.pyenv/versions/3.8.13/lib/python3.8/site-packages/airflow/models/taskinstance.py", line 1544, in signal_handler
    raise AirflowException("Task received SIGTERM signal")
airflow.exceptions.AirflowException: Task received SIGTERM signal
[2022-05-28 16:51:00,532] {taskinstance.py:1396} INFO - Marking task as FAILED. dag_id=Gamer_Daily_Request, task_id=get_lottery, execution_date=20220528T084958, start_date=20220528T085009, end_date=20220528T085100
[2022-05-28 16:51:00,542] {process_utils.py:75} INFO - Process psutil.Process(pid=38040, status='terminated', started='16:50:10') (38040) terminated with exit code None
[2022-05-28 16:51:00,554] {logging_mixin.py:115} WARNING - /Users/user/.pyenv/versions/3.8.13/lib/python3.8/site-packages/airflow/utils/email.py:119 PendingDeprecationWarning: Fetching SMTP credentials from configuration variables will be deprecated in a future release. Please set credentials using a connection instead.
[2022-05-28 16:51:00,554] {configuration.py:549} WARNING - section/key [smtp/smtp_user] not found in config
[2022-05-28 16:51:00,554] {email.py:228} INFO - Email alerting: attempt 1
[2022-05-28 16:51:00,558] {configuration.py:549} WARNING - section/key [smtp/smtp_user] not found in config
[2022-05-28 16:51:00,558] {email.py:228} INFO - Email alerting: attempt 1
[2022-05-28 16:51:00,559] {taskinstance.py:1945} ERROR - Failed to send email to: ['b01201008@gmail.com']
Traceback (most recent call last):
  File "/Users/user/.pyenv/versions/3.8.13/lib/python3.8/site-packages/airflow/models/taskinstance.py", line 1452, in _run_raw_task
    self._execute_task_with_callbacks(context, test_mode)
  File "/Users/user/.pyenv/versions/3.8.13/lib/python3.8/site-packages/airflow/models/taskinstance.py", line 1599, in _execute_task_with_callbacks
    result = self._execute_task(context, task_orig)
  File "/Users/user/.pyenv/versions/3.8.13/lib/python3.8/site-packages/airflow/models/taskinstance.py", line 1660, in _execute_task
    result = execute_callable(context=context)
  File "/Users/user/.pyenv/versions/3.8.13/lib/python3.8/site-packages/airflow/decorators/base.py", line 179, in execute
    return_value = super().execute(context)
  File "/Users/user/.pyenv/versions/3.8.13/lib/python3.8/site-packages/airflow/operators/python.py", line 171, in execute
    return_value = self.execute_callable()
  File "/Users/user/.pyenv/versions/3.8.13/lib/python3.8/site-packages/airflow/operators/python.py", line 189, in execute_callable
    return self.python_callable(*self.op_args, **self.op_kwargs)
  File "/Users/user/flow-for-randy/dags/gamer_dag.py", line 32, in get_lottery
    gamer_service.get_lotteries()
  File "/Users/user/flow-for-randy/dags/services/gamer.py", line 74, in get_lotteries
    self.get_lottery(lottery_page)
  File "/Users/user/flow-for-randy/dags/services/gamer.py", line 66, in get_lottery
    self.watch_ad()
  File "/Users/user/flow-for-randy/dags/services/gamer.py", line 59, in watch_ad
    self.browser.click(GamerElement.close_button)
  File "/Users/user/flow-for-randy/dags/services/drivers/selenium_driver.py", line 32, in click
    self.find_element(el).click()
  File "/Users/user/.pyenv/versions/3.8.13/lib/python3.8/site-packages/selenium/webdriver/remote/webelement.py", line 89, in click
    self._execute(Command.CLICK_ELEMENT)
  File "/Users/user/.pyenv/versions/3.8.13/lib/python3.8/site-packages/selenium/webdriver/remote/webelement.py", line 773, in _execute
    return self._parent.execute(command, params)
  File "/Users/user/.pyenv/versions/3.8.13/lib/python3.8/site-packages/selenium/webdriver/remote/webdriver.py", line 428, in execute
    response = self.command_executor.execute(driver_command, params)
  File "/Users/user/.pyenv/versions/3.8.13/lib/python3.8/site-packages/selenium/webdriver/remote/remote_connection.py", line 347, in execute
    return self._request(command_info[0], url, body=data)
  File "/Users/user/.pyenv/versions/3.8.13/lib/python3.8/site-packages/selenium/webdriver/remote/remote_connection.py", line 369, in _request
    response = self._conn.request(method, url, body=body, headers=headers)
  File "/Users/user/.pyenv/versions/3.8.13/lib/python3.8/site-packages/urllib3/request.py", line 78, in request
    return self.request_encode_body(
  File "/Users/user/.pyenv/versions/3.8.13/lib/python3.8/site-packages/urllib3/request.py", line 170, in request_encode_body
    return self.urlopen(method, url, **extra_kw)
  File "/Users/user/.pyenv/versions/3.8.13/lib/python3.8/site-packages/urllib3/poolmanager.py", line 376, in urlopen
    response = conn.urlopen(method, u.request_uri, **kw)
  File "/Users/user/.pyenv/versions/3.8.13/lib/python3.8/site-packages/urllib3/connectionpool.py", line 703, in urlopen
    httplib_response = self._make_request(
  File "/Users/user/.pyenv/versions/3.8.13/lib/python3.8/site-packages/urllib3/connectionpool.py", line 449, in _make_request
    six.raise_from(e, None)
  File "<string>", line 3, in raise_from
  File "/Users/user/.pyenv/versions/3.8.13/lib/python3.8/site-packages/urllib3/connectionpool.py", line 444, in _make_request
    httplib_response = conn.getresponse()
  File "/Users/user/.pyenv/versions/3.8.13/lib/python3.8/http/client.py", line 1348, in getresponse
    response.begin()
  File "/Users/user/.pyenv/versions/3.8.13/lib/python3.8/http/client.py", line 316, in begin
    version, status, reason = self._read_status()
  File "/Users/user/.pyenv/versions/3.8.13/lib/python3.8/http/client.py", line 277, in _read_status
    line = str(self.fp.readline(_MAXLINE + 1), "iso-8859-1")
  File "/Users/user/.pyenv/versions/3.8.13/lib/python3.8/socket.py", line 669, in readinto
    return self._sock.recv_into(b)
  File "/Users/user/.pyenv/versions/3.8.13/lib/python3.8/site-packages/airflow/models/taskinstance.py", line 1544, in signal_handler
    raise AirflowException("Task received SIGTERM signal")
airflow.exceptions.AirflowException: Task received SIGTERM signal

During handling of the above exception, another exception occurred:

Traceback (most recent call last):
  File "/Users/user/.pyenv/versions/3.8.13/lib/python3.8/site-packages/airflow/models/taskinstance.py", line 2329, in email_alert
    send_email(task.email, subject, html_content)
  File "/Users/user/.pyenv/versions/3.8.13/lib/python3.8/site-packages/airflow/utils/email.py", line 58, in send_email
    return backend(
  File "/Users/user/.pyenv/versions/3.8.13/lib/python3.8/site-packages/airflow/utils/email.py", line 119, in send_email_smtp
    send_mime_email(e_from=mail_from, e_to=recipients, mime_msg=msg, conn_id=conn_id, dryrun=dryrun)
  File "/Users/user/.pyenv/versions/3.8.13/lib/python3.8/site-packages/airflow/utils/email.py", line 230, in send_mime_email
    smtp_conn = _get_smtp_connection(smtp_host, smtp_port, smtp_timeout, smtp_ssl)
  File "/Users/user/.pyenv/versions/3.8.13/lib/python3.8/site-packages/airflow/utils/email.py", line 264, in _get_smtp_connection
    else smtplib.SMTP(host=host, port=port, timeout=timeout)
  File "/Users/user/.pyenv/versions/3.8.13/lib/python3.8/smtplib.py", line 255, in __init__
    (code, msg) = self.connect(host, port)
  File "/Users/user/.pyenv/versions/3.8.13/lib/python3.8/smtplib.py", line 339, in connect
    self.sock = self._get_socket(host, port, self.timeout)
  File "/Users/user/.pyenv/versions/3.8.13/lib/python3.8/smtplib.py", line 310, in _get_socket
    return socket.create_connection((host, port), timeout,
  File "/Users/user/.pyenv/versions/3.8.13/lib/python3.8/socket.py", line 808, in create_connection
    raise err
  File "/Users/user/.pyenv/versions/3.8.13/lib/python3.8/socket.py", line 796, in create_connection
    sock.connect(sa)
ConnectionRefusedError: [Errno 61] Connection refused

During handling of the above exception, another exception occurred:

Traceback (most recent call last):
  File "/Users/user/.pyenv/versions/3.8.13/lib/python3.8/site-packages/airflow/models/taskinstance.py", line 1943, in handle_failure
    self.email_alert(error, task)
  File "/Users/user/.pyenv/versions/3.8.13/lib/python3.8/site-packages/airflow/models/taskinstance.py", line 2331, in email_alert
    send_email(task.email, subject, html_content_err)
  File "/Users/user/.pyenv/versions/3.8.13/lib/python3.8/site-packages/airflow/utils/email.py", line 58, in send_email
    return backend(
  File "/Users/user/.pyenv/versions/3.8.13/lib/python3.8/site-packages/airflow/utils/email.py", line 119, in send_email_smtp
    send_mime_email(e_from=mail_from, e_to=recipients, mime_msg=msg, conn_id=conn_id, dryrun=dryrun)
  File "/Users/user/.pyenv/versions/3.8.13/lib/python3.8/site-packages/airflow/utils/email.py", line 230, in send_mime_email
    smtp_conn = _get_smtp_connection(smtp_host, smtp_port, smtp_timeout, smtp_ssl)
  File "/Users/user/.pyenv/versions/3.8.13/lib/python3.8/site-packages/airflow/utils/email.py", line 264, in _get_smtp_connection
    else smtplib.SMTP(host=host, port=port, timeout=timeout)
  File "/Users/user/.pyenv/versions/3.8.13/lib/python3.8/smtplib.py", line 255, in __init__
    (code, msg) = self.connect(host, port)
  File "/Users/user/.pyenv/versions/3.8.13/lib/python3.8/smtplib.py", line 339, in connect
    self.sock = self._get_socket(host, port, self.timeout)
  File "/Users/user/.pyenv/versions/3.8.13/lib/python3.8/smtplib.py", line 310, in _get_socket
    return socket.create_connection((host, port), timeout,
  File "/Users/user/.pyenv/versions/3.8.13/lib/python3.8/socket.py", line 808, in create_connection
    raise err
  File "/Users/user/.pyenv/versions/3.8.13/lib/python3.8/socket.py", line 796, in create_connection
    sock.connect(sa)
ConnectionRefusedError: [Errno 61] Connection refused
[2022-05-28 16:51:00,567] {standard_task_runner.py:92} ERROR - Failed to execute job 103 for task get_lottery (Task received SIGTERM signal; 38025)
[2022-05-28 16:51:00,601] {process_utils.py:75} INFO - Process psutil.Process(pid=38047, status='terminated', started='16:50:26') (38047) terminated with exit code None
[2022-05-28 16:51:00,601] {process_utils.py:75} INFO - Process psutil.Process(pid=38036, status='terminated', started='16:50:10') (38036) terminated with exit code None
[2022-05-28 16:51:00,601] {process_utils.py:75} INFO - Process psutil.Process(pid=38048, status='terminated', started='16:50:26') (38048) terminated with exit code None
[2022-05-28 16:51:00,601] {process_utils.py:75} INFO - Process psutil.Process(pid=38043, status='terminated', started='16:50:10') (38043) terminated with exit code None
[2022-05-28 16:51:00,602] {process_utils.py:75} INFO - Process psutil.Process(pid=38026, status='terminated', started='16:50:09') (38026) terminated with exit code None
[2022-05-28 16:51:00,704] {process_utils.py:75} INFO - Process psutil.Process(pid=38035, status='terminated', started='16:50:10') (38035) terminated with exit code None
[2022-05-28 16:51:00,716] {process_utils.py:75} INFO - Process psutil.Process(pid=38037, status='terminated', started='16:50:10') (38037) terminated with exit code None
[2022-05-28 16:51:00,736] {process_utils.py:75} INFO - Process psutil.Process(pid=38046, status='terminated', started='16:50:25') (38046) terminated with exit code None
[2022-05-28 16:51:00,755] {process_utils.py:75} INFO - Process psutil.Process(pid=38025, status='terminated', exitcode=1, started='16:50:09') (38025) terminated with exit code 1
[2022-05-28 16:51:00,875] {process_utils.py:75} INFO - Process psutil.Process(pid=38027, status='terminated', started='16:50:09') (38027) terminated with exit code None
