[2022-05-28 14:20:17,662] {taskinstance.py:1160} INFO - Dependencies all met for <TaskInstance: Gamer_Daily_Request.get_lottery manual__2022-05-28T06:20:08.964209+00:00 [queued]>
[2022-05-28 14:20:17,670] {taskinstance.py:1160} INFO - Dependencies all met for <TaskInstance: Gamer_Daily_Request.get_lottery manual__2022-05-28T06:20:08.964209+00:00 [queued]>
[2022-05-28 14:20:17,670] {taskinstance.py:1357} INFO - 
--------------------------------------------------------------------------------
[2022-05-28 14:20:17,670] {taskinstance.py:1358} INFO - Starting attempt 1 of 1
[2022-05-28 14:20:17,670] {taskinstance.py:1359} INFO - 
--------------------------------------------------------------------------------
[2022-05-28 14:20:17,681] {taskinstance.py:1378} INFO - Executing <Task(_PythonDecoratedOperator): get_lottery> on 2022-05-28 06:20:08.964209+00:00
[2022-05-28 14:20:17,683] {standard_task_runner.py:52} INFO - Started process 24900 to run task
[2022-05-28 14:20:17,690] {standard_task_runner.py:79} INFO - Running: ['airflow', 'tasks', 'run', 'Gamer_Daily_Request', 'get_lottery', 'manual__2022-05-28T06:20:08.964209+00:00', '--job-id', '30', '--raw', '--subdir', 'DAGS_FOLDER/gamer_dag.py', '--cfg-path', '/var/folders/7p/8y53sxp17879s6k6nzygbwgw0000gn/T/tmpbsrtkzxh', '--error-file', '/var/folders/7p/8y53sxp17879s6k6nzygbwgw0000gn/T/tmpl7zu9mgc']
[2022-05-28 14:20:17,692] {standard_task_runner.py:80} INFO - Job 30: Subtask get_lottery
[2022-05-28 14:20:17,739] {task_command.py:370} INFO - Running <TaskInstance: Gamer_Daily_Request.get_lottery manual__2022-05-28T06:20:08.964209+00:00 [running]> on host userdeMacBook-Pro.local
[2022-05-28 14:20:17,789] {taskinstance.py:1570} INFO - Exporting the following env vars:
AIRFLOW_CTX_DAG_EMAIL=b01201008@gmail.com
AIRFLOW_CTX_DAG_OWNER=randy
AIRFLOW_CTX_DAG_ID=Gamer_Daily_Request
AIRFLOW_CTX_TASK_ID=get_lottery
AIRFLOW_CTX_EXECUTION_DATE=2022-05-28T06:20:08.964209+00:00
AIRFLOW_CTX_TRY_NUMBER=1
AIRFLOW_CTX_DAG_RUN_ID=manual__2022-05-28T06:20:08.964209+00:00
[2022-05-28 14:20:17,791] {logging_mixin.py:115} INFO - get_lottery
[2022-05-28 14:20:17,798] {logging_mixin.py:115} INFO - ======= cookies ======
[2022-05-28 14:20:17,798] {logging_mixin.py:115} INFO - [{'domain': '.gamer.com.tw', 'expiry': 1716790814, 'httpOnly': False, 'name': '_ga', 'path': '/', 'secure': False, 'value': 'GA1.1.749374459.1653718814'}, {'domain': '.gamer.com.tw', 'expiry': 1653718873, 'httpOnly': False, 'name': '_gat', 'path': '/', 'secure': False, 'value': '1'}, {'domain': '.gamer.com.tw', 'expiry': 1716790814, 'httpOnly': False, 'name': '_ga_2Q21791Y9D', 'path': '/', 'secure': False, 'value': 'GS1.1.1653718814.1.0.1653718814.60'}, {'domain': '.gamer.com.tw', 'expiry': 1653805213, 'httpOnly': False, 'name': '_gid', 'path': '/', 'secure': False, 'value': 'GA1.3.1613808710.1653718814'}]
[2022-05-28 14:20:17,799] {logging_mixin.py:115} INFO - ============================================================
[2022-05-28 14:20:19,775] {taskinstance.py:1890} ERROR - Task failed with exception
Traceback (most recent call last):
  File "/Users/user/.pyenv/versions/3.8.13/lib/python3.8/site-packages/airflow/decorators/base.py", line 179, in execute
    return_value = super().execute(context)
  File "/Users/user/.pyenv/versions/3.8.13/lib/python3.8/site-packages/airflow/operators/python.py", line 171, in execute
    return_value = self.execute_callable()
  File "/Users/user/.pyenv/versions/3.8.13/lib/python3.8/site-packages/airflow/operators/python.py", line 189, in execute_callable
    return self.python_callable(*self.op_args, **self.op_kwargs)
  File "/Users/user/flow-for-randy/dags/gamer_dag.py", line 31, in get_lottery
    gamer_service.login()
  File "/Users/user/flow-for-randy/dags/services/gamer.py", line 26, in login
    self.web_driver.load_cookies(self.cookies)
  File "/Users/user/flow-for-randy/dags/services/drivers/selenium_driver.py", line 33, in load_cookies
    self.driver.add_cookie(cookie)
  File "/Users/user/.pyenv/versions/3.8.13/lib/python3.8/site-packages/selenium/webdriver/remote/webdriver.py", line 1136, in add_cookie
    self.execute(Command.ADD_COOKIE, {'cookie': cookie_dict})
  File "/Users/user/.pyenv/versions/3.8.13/lib/python3.8/site-packages/selenium/webdriver/remote/webdriver.py", line 430, in execute
    self.error_handler.check_response(response)
  File "/Users/user/.pyenv/versions/3.8.13/lib/python3.8/site-packages/selenium/webdriver/remote/errorhandler.py", line 247, in check_response
    raise exception_class(message, screen, stacktrace)
selenium.common.exceptions.InvalidCookieDomainException: Message: invalid cookie domain
  (Session info: chrome=102.0.5005.61)
Stacktrace:
0   chromedriver                        0x000000011016dd19 chromedriver + 5197081
1   chromedriver                        0x00000001100fbb23 chromedriver + 4729635
2   chromedriver                        0x000000010fcd916f chromedriver + 393583
3   chromedriver                        0x000000010fd4ecb6 chromedriver + 875702
4   chromedriver                        0x000000010fd2b802 chromedriver + 731138
5   chromedriver                        0x000000010fd3e2a1 chromedriver + 807585
6   chromedriver                        0x000000010fd2b6f3 chromedriver + 730867
7   chromedriver                        0x000000010fd01a49 chromedriver + 559689
8   chromedriver                        0x000000010fd02a75 chromedriver + 563829
9   chromedriver                        0x000000011013fbdd chromedriver + 5008349
10  chromedriver                        0x0000000110144b64 chromedriver + 5028708
11  chromedriver                        0x0000000110149bcf chromedriver + 5049295
12  chromedriver                        0x00000001101457ca chromedriver + 5031882
13  chromedriver                        0x000000011011f59f chromedriver + 4875679
14  chromedriver                        0x000000011015f388 chromedriver + 5137288
15  chromedriver                        0x000000011015f50f chromedriver + 5137679
16  chromedriver                        0x0000000110175085 chromedriver + 5226629
17  libsystem_pthread.dylib             0x00007ff819e344e1 _pthread_start + 125
18  libsystem_pthread.dylib             0x00007ff819e2ff6b thread_start + 15

[2022-05-28 14:20:19,792] {taskinstance.py:1396} INFO - Marking task as FAILED. dag_id=Gamer_Daily_Request, task_id=get_lottery, execution_date=20220528T062008, start_date=20220528T062017, end_date=20220528T062019
[2022-05-28 14:20:19,831] {logging_mixin.py:115} WARNING - /Users/user/.pyenv/versions/3.8.13/lib/python3.8/site-packages/airflow/utils/email.py:119 PendingDeprecationWarning: Fetching SMTP credentials from configuration variables will be deprecated in a future release. Please set credentials using a connection instead.
[2022-05-28 14:20:19,861] {configuration.py:549} WARNING - section/key [smtp/smtp_user] not found in config
[2022-05-28 14:20:19,863] {email.py:228} INFO - Email alerting: attempt 1
[2022-05-28 14:20:19,887] {configuration.py:549} WARNING - section/key [smtp/smtp_user] not found in config
[2022-05-28 14:20:19,902] {email.py:228} INFO - Email alerting: attempt 1
[2022-05-28 14:20:19,922] {taskinstance.py:1945} ERROR - Failed to send email to: ['b01201008@gmail.com']
Traceback (most recent call last):
  File "/Users/user/.pyenv/versions/3.8.13/lib/python3.8/site-packages/airflow/models/taskinstance.py", line 1452, in _run_raw_task
    self._execute_task_with_callbacks(context, test_mode)
  File "/Users/user/.pyenv/versions/3.8.13/lib/python3.8/site-packages/airflow/models/taskinstance.py", line 1599, in _execute_task_with_callbacks
    result = self._execute_task(context, task_orig)
  File "/Users/user/.pyenv/versions/3.8.13/lib/python3.8/site-packages/airflow/models/taskinstance.py", line 1660, in _execute_task
    result = execute_callable(context=context)
  File "/Users/user/.pyenv/versions/3.8.13/lib/python3.8/site-packages/airflow/decorators/base.py", line 179, in execute
    return_value = super().execute(context)
  File "/Users/user/.pyenv/versions/3.8.13/lib/python3.8/site-packages/airflow/operators/python.py", line 171, in execute
    return_value = self.execute_callable()
  File "/Users/user/.pyenv/versions/3.8.13/lib/python3.8/site-packages/airflow/operators/python.py", line 189, in execute_callable
    return self.python_callable(*self.op_args, **self.op_kwargs)
  File "/Users/user/flow-for-randy/dags/gamer_dag.py", line 31, in get_lottery
    gamer_service.login()
  File "/Users/user/flow-for-randy/dags/services/gamer.py", line 26, in login
    self.web_driver.load_cookies(self.cookies)
  File "/Users/user/flow-for-randy/dags/services/drivers/selenium_driver.py", line 33, in load_cookies
    self.driver.add_cookie(cookie)
  File "/Users/user/.pyenv/versions/3.8.13/lib/python3.8/site-packages/selenium/webdriver/remote/webdriver.py", line 1136, in add_cookie
    self.execute(Command.ADD_COOKIE, {'cookie': cookie_dict})
  File "/Users/user/.pyenv/versions/3.8.13/lib/python3.8/site-packages/selenium/webdriver/remote/webdriver.py", line 430, in execute
    self.error_handler.check_response(response)
  File "/Users/user/.pyenv/versions/3.8.13/lib/python3.8/site-packages/selenium/webdriver/remote/errorhandler.py", line 247, in check_response
    raise exception_class(message, screen, stacktrace)
selenium.common.exceptions.InvalidCookieDomainException: Message: invalid cookie domain
  (Session info: chrome=102.0.5005.61)
Stacktrace:
0   chromedriver                        0x000000011016dd19 chromedriver + 5197081
1   chromedriver                        0x00000001100fbb23 chromedriver + 4729635
2   chromedriver                        0x000000010fcd916f chromedriver + 393583
3   chromedriver                        0x000000010fd4ecb6 chromedriver + 875702
4   chromedriver                        0x000000010fd2b802 chromedriver + 731138
5   chromedriver                        0x000000010fd3e2a1 chromedriver + 807585
6   chromedriver                        0x000000010fd2b6f3 chromedriver + 730867
7   chromedriver                        0x000000010fd01a49 chromedriver + 559689
8   chromedriver                        0x000000010fd02a75 chromedriver + 563829
9   chromedriver                        0x000000011013fbdd chromedriver + 5008349
10  chromedriver                        0x0000000110144b64 chromedriver + 5028708
11  chromedriver                        0x0000000110149bcf chromedriver + 5049295
12  chromedriver                        0x00000001101457ca chromedriver + 5031882
13  chromedriver                        0x000000011011f59f chromedriver + 4875679
14  chromedriver                        0x000000011015f388 chromedriver + 5137288
15  chromedriver                        0x000000011015f50f chromedriver + 5137679
16  chromedriver                        0x0000000110175085 chromedriver + 5226629
17  libsystem_pthread.dylib             0x00007ff819e344e1 _pthread_start + 125
18  libsystem_pthread.dylib             0x00007ff819e2ff6b thread_start + 15


During handling of the above exception, another exception occurred:

Traceback (most recent call last):
  File "/Users/user/.pyenv/versions/3.8.13/lib/python3.8/site-packages/airflow/models/taskinstance.py", line 2329, in email_alert
    send_email(task.email, subject, html_content)
  File "/Users/user/.pyenv/versions/3.8.13/lib/python3.8/site-packages/airflow/utils/email.py", line 58, in send_email
    return backend(
  File "/Users/user/.pyenv/versions/3.8.13/lib/python3.8/site-packages/airflow/utils/email.py", line 119, in send_email_smtp
    send_mime_email(e_from=mail_from, e_to=recipients, mime_msg=msg, conn_id=conn_id, dryrun=dryrun)
  File "/Users/user/.pyenv/versions/3.8.13/lib/python3.8/site-packages/airflow/utils/email.py", line 230, in send_mime_email
    smtp_conn = _get_smtp_connection(smtp_host, smtp_port, smtp_timeout, smtp_ssl)
  File "/Users/user/.pyenv/versions/3.8.13/lib/python3.8/site-packages/airflow/utils/email.py", line 264, in _get_smtp_connection
    else smtplib.SMTP(host=host, port=port, timeout=timeout)
  File "/Users/user/.pyenv/versions/3.8.13/lib/python3.8/smtplib.py", line 255, in __init__
    (code, msg) = self.connect(host, port)
  File "/Users/user/.pyenv/versions/3.8.13/lib/python3.8/smtplib.py", line 339, in connect
    self.sock = self._get_socket(host, port, self.timeout)
  File "/Users/user/.pyenv/versions/3.8.13/lib/python3.8/smtplib.py", line 310, in _get_socket
    return socket.create_connection((host, port), timeout,
  File "/Users/user/.pyenv/versions/3.8.13/lib/python3.8/socket.py", line 808, in create_connection
    raise err
  File "/Users/user/.pyenv/versions/3.8.13/lib/python3.8/socket.py", line 796, in create_connection
    sock.connect(sa)
ConnectionRefusedError: [Errno 61] Connection refused

During handling of the above exception, another exception occurred:

Traceback (most recent call last):
  File "/Users/user/.pyenv/versions/3.8.13/lib/python3.8/site-packages/airflow/models/taskinstance.py", line 1943, in handle_failure
    self.email_alert(error, task)
  File "/Users/user/.pyenv/versions/3.8.13/lib/python3.8/site-packages/airflow/models/taskinstance.py", line 2331, in email_alert
    send_email(task.email, subject, html_content_err)
  File "/Users/user/.pyenv/versions/3.8.13/lib/python3.8/site-packages/airflow/utils/email.py", line 58, in send_email
    return backend(
  File "/Users/user/.pyenv/versions/3.8.13/lib/python3.8/site-packages/airflow/utils/email.py", line 119, in send_email_smtp
    send_mime_email(e_from=mail_from, e_to=recipients, mime_msg=msg, conn_id=conn_id, dryrun=dryrun)
  File "/Users/user/.pyenv/versions/3.8.13/lib/python3.8/site-packages/airflow/utils/email.py", line 230, in send_mime_email
    smtp_conn = _get_smtp_connection(smtp_host, smtp_port, smtp_timeout, smtp_ssl)
  File "/Users/user/.pyenv/versions/3.8.13/lib/python3.8/site-packages/airflow/utils/email.py", line 264, in _get_smtp_connection
    else smtplib.SMTP(host=host, port=port, timeout=timeout)
  File "/Users/user/.pyenv/versions/3.8.13/lib/python3.8/smtplib.py", line 255, in __init__
    (code, msg) = self.connect(host, port)
  File "/Users/user/.pyenv/versions/3.8.13/lib/python3.8/smtplib.py", line 339, in connect
    self.sock = self._get_socket(host, port, self.timeout)
  File "/Users/user/.pyenv/versions/3.8.13/lib/python3.8/smtplib.py", line 310, in _get_socket
    return socket.create_connection((host, port), timeout,
  File "/Users/user/.pyenv/versions/3.8.13/lib/python3.8/socket.py", line 808, in create_connection
    raise err
  File "/Users/user/.pyenv/versions/3.8.13/lib/python3.8/socket.py", line 796, in create_connection
    sock.connect(sa)
ConnectionRefusedError: [Errno 61] Connection refused
[2022-05-28 14:20:20,002] {standard_task_runner.py:92} ERROR - Failed to execute job 30 for task get_lottery (Message: invalid cookie domain
  (Session info: chrome=102.0.5005.61)
Stacktrace:
0   chromedriver                        0x000000011016dd19 chromedriver + 5197081
1   chromedriver                        0x00000001100fbb23 chromedriver + 4729635
2   chromedriver                        0x000000010fcd916f chromedriver + 393583
3   chromedriver                        0x000000010fd4ecb6 chromedriver + 875702
4   chromedriver                        0x000000010fd2b802 chromedriver + 731138
5   chromedriver                        0x000000010fd3e2a1 chromedriver + 807585
6   chromedriver                        0x000000010fd2b6f3 chromedriver + 730867
7   chromedriver                        0x000000010fd01a49 chromedriver + 559689
8   chromedriver                        0x000000010fd02a75 chromedriver + 563829
9   chromedriver                        0x000000011013fbdd chromedriver + 5008349
10  chromedriver                        0x0000000110144b64 chromedriver + 5028708
11  chromedriver                        0x0000000110149bcf chromedriver + 5049295
12  chromedriver                        0x00000001101457ca chromedriver + 5031882
13  chromedriver                        0x000000011011f59f chromedriver + 4875679
14  chromedriver                        0x000000011015f388 chromedriver + 5137288
15  chromedriver                        0x000000011015f50f chromedriver + 5137679
16  chromedriver                        0x0000000110175085 chromedriver + 5226629
17  libsystem_pthread.dylib             0x00007ff819e344e1 _pthread_start + 125
18  libsystem_pthread.dylib             0x00007ff819e2ff6b thread_start + 15
; 24900)
[2022-05-28 14:20:20,060] {local_task_job.py:156} INFO - Task exited with return code 1
[2022-05-28 14:20:20,104] {local_task_job.py:273} INFO - 0 downstream tasks scheduled from follow-on schedule check
