[2022-05-28 15:34:01,975] {taskinstance.py:1160} INFO - Dependencies all met for <TaskInstance: Gamer_Daily_Request.login manual__2022-05-28T07:33:59.496931+00:00 [queued]>
[2022-05-28 15:34:01,982] {taskinstance.py:1160} INFO - Dependencies all met for <TaskInstance: Gamer_Daily_Request.login manual__2022-05-28T07:33:59.496931+00:00 [queued]>
[2022-05-28 15:34:01,982] {taskinstance.py:1357} INFO - 
--------------------------------------------------------------------------------
[2022-05-28 15:34:01,982] {taskinstance.py:1358} INFO - Starting attempt 1 of 1
[2022-05-28 15:34:01,982] {taskinstance.py:1359} INFO - 
--------------------------------------------------------------------------------
[2022-05-28 15:34:01,994] {taskinstance.py:1378} INFO - Executing <Task(_PythonDecoratedOperator): login> on 2022-05-28 07:33:59.496931+00:00
[2022-05-28 15:34:01,997] {standard_task_runner.py:52} INFO - Started process 31383 to run task
[2022-05-28 15:34:02,003] {standard_task_runner.py:79} INFO - Running: ['airflow', 'tasks', 'run', 'Gamer_Daily_Request', 'login', 'manual__2022-05-28T07:33:59.496931+00:00', '--job-id', '59', '--raw', '--subdir', 'DAGS_FOLDER/gamer_dag.py', '--cfg-path', '/var/folders/7p/8y53sxp17879s6k6nzygbwgw0000gn/T/tmpkg4blm4n', '--error-file', '/var/folders/7p/8y53sxp17879s6k6nzygbwgw0000gn/T/tmph33lsh8n']
[2022-05-28 15:34:02,004] {standard_task_runner.py:80} INFO - Job 59: Subtask login
[2022-05-28 15:34:02,049] {task_command.py:370} INFO - Running <TaskInstance: Gamer_Daily_Request.login manual__2022-05-28T07:33:59.496931+00:00 [running]> on host userdeMacBook-Pro.local
[2022-05-28 15:34:02,090] {taskinstance.py:1570} INFO - Exporting the following env vars:
AIRFLOW_CTX_DAG_EMAIL=b01201008@gmail.com
AIRFLOW_CTX_DAG_OWNER=randy
AIRFLOW_CTX_DAG_ID=Gamer_Daily_Request
AIRFLOW_CTX_TASK_ID=login
AIRFLOW_CTX_EXECUTION_DATE=2022-05-28T07:33:59.496931+00:00
AIRFLOW_CTX_TRY_NUMBER=1
AIRFLOW_CTX_DAG_RUN_ID=manual__2022-05-28T07:33:59.496931+00:00
[2022-05-28 15:34:02,091] {logging_mixin.py:115} INFO - login
[2022-05-28 15:34:07,033] {local_task_job.py:193} ERROR - The recorded hostname userdeMacBook-Pro.local does not match this instance's hostname 1.0.0.0.0.0.0.0.0.0.0.0.0.0.0.0.0.0.0.0.0.0.0.0.0.0.0.0.0.0.0.0.ip6.arpa
[2022-05-28 15:34:07,045] {process_utils.py:125} INFO - Sending Signals.SIGTERM to group 31383. PIDs of all processes in the group: [31384, 31385, 31396, 31397, 31398, 31401, 31404, 31405, 31383]
[2022-05-28 15:34:07,045] {process_utils.py:80} INFO - Sending the signal Signals.SIGTERM to group 31383
[2022-05-28 15:34:07,045] {taskinstance.py:1542} ERROR - Received SIGTERM. Terminating subprocesses.
[2022-05-28 15:34:07,094] {taskinstance.py:1890} ERROR - Task failed with exception
Traceback (most recent call last):
  File "/Users/user/.pyenv/versions/3.8.13/lib/python3.8/site-packages/airflow/decorators/base.py", line 179, in execute
    return_value = super().execute(context)
  File "/Users/user/.pyenv/versions/3.8.13/lib/python3.8/site-packages/airflow/operators/python.py", line 171, in execute
    return_value = self.execute_callable()
  File "/Users/user/.pyenv/versions/3.8.13/lib/python3.8/site-packages/airflow/operators/python.py", line 189, in execute_callable
    return self.python_callable(*self.op_args, **self.op_kwargs)
  File "/Users/user/flow-for-randy/dags/gamer_dag.py", line 20, in login
    ti.xcom_push("gamer_cookies", gamer_service.browser.get_cookies())
  File "/Users/user/flow-for-randy/dags/services/drivers/selenium_driver.py", line 31, in get_cookies
    return self.driver.get_cookies()
  File "/Users/user/.pyenv/versions/3.8.13/lib/python3.8/site-packages/selenium/webdriver/remote/webdriver.py", line 1079, in get_cookies
    return self.execute(Command.GET_ALL_COOKIES)['value']
  File "/Users/user/.pyenv/versions/3.8.13/lib/python3.8/site-packages/selenium/webdriver/remote/webdriver.py", line 428, in execute
    response = self.command_executor.execute(driver_command, params)
  File "/Users/user/.pyenv/versions/3.8.13/lib/python3.8/site-packages/selenium/webdriver/remote/remote_connection.py", line 347, in execute
    return self._request(command_info[0], url, body=data)
  File "/Users/user/.pyenv/versions/3.8.13/lib/python3.8/site-packages/selenium/webdriver/remote/remote_connection.py", line 369, in _request
    response = self._conn.request(method, url, body=body, headers=headers)
  File "/Users/user/.pyenv/versions/3.8.13/lib/python3.8/site-packages/urllib3/request.py", line 74, in request
    return self.request_encode_url(
  File "/Users/user/.pyenv/versions/3.8.13/lib/python3.8/site-packages/urllib3/request.py", line 96, in request_encode_url
    return self.urlopen(method, url, **extra_kw)
  File "/Users/user/.pyenv/versions/3.8.13/lib/python3.8/site-packages/urllib3/poolmanager.py", line 376, in urlopen
    response = conn.urlopen(method, u.request_uri, **kw)
  File "/Users/user/.pyenv/versions/3.8.13/lib/python3.8/site-packages/urllib3/connectionpool.py", line 703, in urlopen
    httplib_response = self._make_request(
  File "/Users/user/.pyenv/versions/3.8.13/lib/python3.8/site-packages/urllib3/connectionpool.py", line 449, in _make_request
    six.raise_from(e, None)
  File "<string>", line 3, in raise_from
  File "/Users/user/.pyenv/versions/3.8.13/lib/python3.8/site-packages/urllib3/connectionpool.py", line 444, in _make_request
    httplib_response = conn.getresponse()
  File "/Users/user/.pyenv/versions/3.8.13/lib/python3.8/http/client.py", line 1348, in getresponse
    response.begin()
  File "/Users/user/.pyenv/versions/3.8.13/lib/python3.8/http/client.py", line 316, in begin
    version, status, reason = self._read_status()
  File "/Users/user/.pyenv/versions/3.8.13/lib/python3.8/http/client.py", line 277, in _read_status
    line = str(self.fp.readline(_MAXLINE + 1), "iso-8859-1")
  File "/Users/user/.pyenv/versions/3.8.13/lib/python3.8/socket.py", line 669, in readinto
    return self._sock.recv_into(b)
  File "/Users/user/.pyenv/versions/3.8.13/lib/python3.8/site-packages/airflow/models/taskinstance.py", line 1544, in signal_handler
    raise AirflowException("Task received SIGTERM signal")
airflow.exceptions.AirflowException: Task received SIGTERM signal
[2022-05-28 15:34:07,106] {process_utils.py:75} INFO - Process psutil.Process(pid=31401, status='terminated', started='15:34:03') (31401) terminated with exit code None
[2022-05-28 15:34:07,124] {process_utils.py:75} INFO - Process psutil.Process(pid=31398, status='terminated', started='15:34:02') (31398) terminated with exit code None
[2022-05-28 15:34:07,127] {taskinstance.py:1396} INFO - Marking task as FAILED. dag_id=Gamer_Daily_Request, task_id=login, execution_date=20220528T073359, start_date=20220528T073401, end_date=20220528T073407
[2022-05-28 15:34:07,184] {logging_mixin.py:115} WARNING - /Users/user/.pyenv/versions/3.8.13/lib/python3.8/site-packages/airflow/utils/email.py:119 PendingDeprecationWarning: Fetching SMTP credentials from configuration variables will be deprecated in a future release. Please set credentials using a connection instead.
[2022-05-28 15:34:07,202] {configuration.py:549} WARNING - section/key [smtp/smtp_user] not found in config
[2022-05-28 15:34:07,220] {email.py:228} INFO - Email alerting: attempt 1
[2022-05-28 15:34:07,225] {configuration.py:549} WARNING - section/key [smtp/smtp_user] not found in config
[2022-05-28 15:34:07,226] {email.py:228} INFO - Email alerting: attempt 1
[2022-05-28 15:34:07,227] {taskinstance.py:1945} ERROR - Failed to send email to: ['b01201008@gmail.com']
Traceback (most recent call last):
  File "/Users/user/.pyenv/versions/3.8.13/lib/python3.8/site-packages/airflow/models/taskinstance.py", line 1452, in _run_raw_task
    self._execute_task_with_callbacks(context, test_mode)
  File "/Users/user/.pyenv/versions/3.8.13/lib/python3.8/site-packages/airflow/models/taskinstance.py", line 1599, in _execute_task_with_callbacks
    result = self._execute_task(context, task_orig)
  File "/Users/user/.pyenv/versions/3.8.13/lib/python3.8/site-packages/airflow/models/taskinstance.py", line 1660, in _execute_task
    result = execute_callable(context=context)
  File "/Users/user/.pyenv/versions/3.8.13/lib/python3.8/site-packages/airflow/decorators/base.py", line 179, in execute
    return_value = super().execute(context)
  File "/Users/user/.pyenv/versions/3.8.13/lib/python3.8/site-packages/airflow/operators/python.py", line 171, in execute
    return_value = self.execute_callable()
  File "/Users/user/.pyenv/versions/3.8.13/lib/python3.8/site-packages/airflow/operators/python.py", line 189, in execute_callable
    return self.python_callable(*self.op_args, **self.op_kwargs)
  File "/Users/user/flow-for-randy/dags/gamer_dag.py", line 20, in login
    ti.xcom_push("gamer_cookies", gamer_service.browser.get_cookies())
  File "/Users/user/flow-for-randy/dags/services/drivers/selenium_driver.py", line 31, in get_cookies
    return self.driver.get_cookies()
  File "/Users/user/.pyenv/versions/3.8.13/lib/python3.8/site-packages/selenium/webdriver/remote/webdriver.py", line 1079, in get_cookies
    return self.execute(Command.GET_ALL_COOKIES)['value']
  File "/Users/user/.pyenv/versions/3.8.13/lib/python3.8/site-packages/selenium/webdriver/remote/webdriver.py", line 428, in execute
    response = self.command_executor.execute(driver_command, params)
  File "/Users/user/.pyenv/versions/3.8.13/lib/python3.8/site-packages/selenium/webdriver/remote/remote_connection.py", line 347, in execute
    return self._request(command_info[0], url, body=data)
  File "/Users/user/.pyenv/versions/3.8.13/lib/python3.8/site-packages/selenium/webdriver/remote/remote_connection.py", line 369, in _request
    response = self._conn.request(method, url, body=body, headers=headers)
  File "/Users/user/.pyenv/versions/3.8.13/lib/python3.8/site-packages/urllib3/request.py", line 74, in request
    return self.request_encode_url(
  File "/Users/user/.pyenv/versions/3.8.13/lib/python3.8/site-packages/urllib3/request.py", line 96, in request_encode_url
    return self.urlopen(method, url, **extra_kw)
  File "/Users/user/.pyenv/versions/3.8.13/lib/python3.8/site-packages/urllib3/poolmanager.py", line 376, in urlopen
    response = conn.urlopen(method, u.request_uri, **kw)
  File "/Users/user/.pyenv/versions/3.8.13/lib/python3.8/site-packages/urllib3/connectionpool.py", line 703, in urlopen
    httplib_response = self._make_request(
  File "/Users/user/.pyenv/versions/3.8.13/lib/python3.8/site-packages/urllib3/connectionpool.py", line 449, in _make_request
    six.raise_from(e, None)
  File "<string>", line 3, in raise_from
  File "/Users/user/.pyenv/versions/3.8.13/lib/python3.8/site-packages/urllib3/connectionpool.py", line 444, in _make_request
    httplib_response = conn.getresponse()
  File "/Users/user/.pyenv/versions/3.8.13/lib/python3.8/http/client.py", line 1348, in getresponse
    response.begin()
  File "/Users/user/.pyenv/versions/3.8.13/lib/python3.8/http/client.py", line 316, in begin
    version, status, reason = self._read_status()
  File "/Users/user/.pyenv/versions/3.8.13/lib/python3.8/http/client.py", line 277, in _read_status
    line = str(self.fp.readline(_MAXLINE + 1), "iso-8859-1")
  File "/Users/user/.pyenv/versions/3.8.13/lib/python3.8/socket.py", line 669, in readinto
    return self._sock.recv_into(b)
  File "/Users/user/.pyenv/versions/3.8.13/lib/python3.8/site-packages/airflow/models/taskinstance.py", line 1544, in signal_handler
    raise AirflowException("Task received SIGTERM signal")
airflow.exceptions.AirflowException: Task received SIGTERM signal

During handling of the above exception, another exception occurred:

Traceback (most recent call last):
  File "/Users/user/.pyenv/versions/3.8.13/lib/python3.8/site-packages/airflow/models/taskinstance.py", line 2329, in email_alert
    send_email(task.email, subject, html_content)
  File "/Users/user/.pyenv/versions/3.8.13/lib/python3.8/site-packages/airflow/utils/email.py", line 58, in send_email
    return backend(
  File "/Users/user/.pyenv/versions/3.8.13/lib/python3.8/site-packages/airflow/utils/email.py", line 119, in send_email_smtp
    send_mime_email(e_from=mail_from, e_to=recipients, mime_msg=msg, conn_id=conn_id, dryrun=dryrun)
  File "/Users/user/.pyenv/versions/3.8.13/lib/python3.8/site-packages/airflow/utils/email.py", line 230, in send_mime_email
    smtp_conn = _get_smtp_connection(smtp_host, smtp_port, smtp_timeout, smtp_ssl)
  File "/Users/user/.pyenv/versions/3.8.13/lib/python3.8/site-packages/airflow/utils/email.py", line 264, in _get_smtp_connection
    else smtplib.SMTP(host=host, port=port, timeout=timeout)
  File "/Users/user/.pyenv/versions/3.8.13/lib/python3.8/smtplib.py", line 255, in __init__
    (code, msg) = self.connect(host, port)
  File "/Users/user/.pyenv/versions/3.8.13/lib/python3.8/smtplib.py", line 339, in connect
    self.sock = self._get_socket(host, port, self.timeout)
  File "/Users/user/.pyenv/versions/3.8.13/lib/python3.8/smtplib.py", line 310, in _get_socket
    return socket.create_connection((host, port), timeout,
  File "/Users/user/.pyenv/versions/3.8.13/lib/python3.8/socket.py", line 808, in create_connection
    raise err
  File "/Users/user/.pyenv/versions/3.8.13/lib/python3.8/socket.py", line 796, in create_connection
    sock.connect(sa)
ConnectionRefusedError: [Errno 61] Connection refused

During handling of the above exception, another exception occurred:

Traceback (most recent call last):
  File "/Users/user/.pyenv/versions/3.8.13/lib/python3.8/site-packages/airflow/models/taskinstance.py", line 1943, in handle_failure
    self.email_alert(error, task)
  File "/Users/user/.pyenv/versions/3.8.13/lib/python3.8/site-packages/airflow/models/taskinstance.py", line 2331, in email_alert
    send_email(task.email, subject, html_content_err)
  File "/Users/user/.pyenv/versions/3.8.13/lib/python3.8/site-packages/airflow/utils/email.py", line 58, in send_email
    return backend(
  File "/Users/user/.pyenv/versions/3.8.13/lib/python3.8/site-packages/airflow/utils/email.py", line 119, in send_email_smtp
    send_mime_email(e_from=mail_from, e_to=recipients, mime_msg=msg, conn_id=conn_id, dryrun=dryrun)
  File "/Users/user/.pyenv/versions/3.8.13/lib/python3.8/site-packages/airflow/utils/email.py", line 230, in send_mime_email
    smtp_conn = _get_smtp_connection(smtp_host, smtp_port, smtp_timeout, smtp_ssl)
  File "/Users/user/.pyenv/versions/3.8.13/lib/python3.8/site-packages/airflow/utils/email.py", line 264, in _get_smtp_connection
    else smtplib.SMTP(host=host, port=port, timeout=timeout)
  File "/Users/user/.pyenv/versions/3.8.13/lib/python3.8/smtplib.py", line 255, in __init__
    (code, msg) = self.connect(host, port)
  File "/Users/user/.pyenv/versions/3.8.13/lib/python3.8/smtplib.py", line 339, in connect
    self.sock = self._get_socket(host, port, self.timeout)
  File "/Users/user/.pyenv/versions/3.8.13/lib/python3.8/smtplib.py", line 310, in _get_socket
    return socket.create_connection((host, port), timeout,
  File "/Users/user/.pyenv/versions/3.8.13/lib/python3.8/socket.py", line 808, in create_connection
    raise err
  File "/Users/user/.pyenv/versions/3.8.13/lib/python3.8/socket.py", line 796, in create_connection
    sock.connect(sa)
ConnectionRefusedError: [Errno 61] Connection refused
[2022-05-28 15:34:07,238] {standard_task_runner.py:92} ERROR - Failed to execute job 59 for task login (Task received SIGTERM signal; 31383)
[2022-05-28 15:34:07,264] {process_utils.py:75} INFO - Process psutil.Process(pid=31385, status='terminated', started='15:34:02') (31385) terminated with exit code None
[2022-05-28 15:34:07,264] {process_utils.py:75} INFO - Process psutil.Process(pid=31396, status='terminated', started='15:34:02') (31396) terminated with exit code None
[2022-05-28 15:34:07,264] {process_utils.py:75} INFO - Process psutil.Process(pid=31383, status='terminated', exitcode=1, started='15:34:01') (31383) terminated with exit code 1
[2022-05-28 15:34:07,264] {process_utils.py:75} INFO - Process psutil.Process(pid=31397, status='terminated', started='15:34:02') (31397) terminated with exit code None
[2022-05-28 15:34:07,265] {process_utils.py:75} INFO - Process psutil.Process(pid=31384, status='terminated', started='15:34:02') (31384) terminated with exit code None
[2022-05-28 15:34:07,265] {process_utils.py:75} INFO - Process psutil.Process(pid=31405, status='terminated', started='15:34:05') (31405) terminated with exit code None
[2022-05-28 15:34:07,265] {process_utils.py:75} INFO - Process psutil.Process(pid=31404, status='terminated', started='15:34:03') (31404) terminated with exit code None
